<robot
  name="scorpio_arm_description_v3">
  <link
    name="base_link">
    <inertial>
      <origin
        xyz="-0.0023174739871849 0.000926090335802019 0.0320057013975666"
        rpy="0 0 0" />
      <mass
        value="2.11601477785116" />
      <inertia
        ixx="0.00202448875112996"
        ixy="4.37456323015974E-05"
        ixz="0.000128545243673656"
        iyy="0.00131223237035268"
        iyz="-0.000182115234066843"
        izz="0.000782866740229757" />
    </inertial>
    <visual>
      <origin
        xyz="0 0 0"
        rpy="0 0 0" />
      <geometry>
        <mesh
          filename="package://scorpio_arm_description_v3/meshes/base_link.STL" />
      </geometry>
      <material
        name="">
        <color
          rgba="0.792156862745098 0.819607843137255 0.933333333333333 1" />
      </material>
    </visual>
    <collision>
      <origin
        xyz="0 0 0"
        rpy="0 0 0" />
      <geometry>
        <mesh
          filename="package://scorpio_arm_description_v3/meshes/base_link.STL" />
      </geometry>
    </collision>
  </link>
  <link
    name="link1">
    <inertial>
      <origin
        xyz="0.000477211763040632 -0.00737171225105655 0.0673262959495374"
        rpy="0 0 0" />
      <mass
        value="0.462790481374202" />
      <inertia
        ixx="0.000939965910200995"
        ixy="1.64506977488456E-06"
        ixz="2.63906539352487E-05"
        iyy="0.00212746857726697"
        iyz="0.000232679816143088"
        izz="0.00200259662994076" />
    </inertial>
    <visual>
      <origin
        xyz="0 0 0"
        rpy="0 0 0" />
      <geometry>
        <mesh
          filename="package://scorpio_arm_description_v3/meshes/link1.STL" />
      </geometry>
      <material
        name="">
        <color
          rgba="0.752941176470588 0.752941176470588 0.752941176470588 1" />
      </material>
    </visual>
    <collision>
      <origin
        xyz="0 0 0"
        rpy="0 0 0" />
      <geometry>
        <mesh
          filename="package://scorpio_arm_description_v3/meshes/link1.STL" />
      </geometry>
    </collision>
  </link>
  <joint
    name="joint1"
    type="revolute">
    <origin
      xyz="0 0 0.1115"
      rpy="1.65436122510606E-24 -2.16239755607771E-34 1.77925042286121E-10" />
    <parent
      link="base_link" />
    <child
      link="link1" />
    <axis
      xyz="0 0 1" />
  </joint>
  <link
    name="link2">
    <inertial>
      <origin
        xyz="0.000424568456060081 0.353718613538131 -0.0239145484479153"
        rpy="0 0 0" />
      <mass
        value="0.449203640099021" />
      <inertia
        ixx="0.00153786121682179"
        ixy="-8.28836534643507E-05"
        ixz="-8.85331181664693E-06"
        iyy="0.000798472791972848"
        iyz="0.000260149183654035"
        izz="0.00223846447973204" />
    </inertial>
    <visual>
      <origin
        xyz="0 0 0"
        rpy="0 0 0" />
      <geometry>
        <mesh
          filename="package://scorpio_arm_description_v3/meshes/link2.STL" />
      </geometry>
      <material
        name="">
        <color
          rgba="0.752941176470588 0.752941176470588 0.752941176470588 1" />
      </material>
    </visual>
    <collision>
      <origin
        xyz="0 0 0"
        rpy="0 0 0" />
      <geometry>
        <mesh
          filename="package://scorpio_arm_description_v3/meshes/link2.STL" />
      </geometry>
    </collision>
  </link>
  <joint
    name="joint2"
    type="revolute">
    <origin
      xyz="0 -0.00775000309120119 0.314499999923826"
      rpy="1.57079631696602 1.748803E-18 3.14159265358979" />
    <parent
      link="link1" />
    <child
      link="link2" />
    <axis
      xyz="0 0 -1" />
  </joint>
  <link
    name="link3">
    <inertial>
      <origin
        xyz="0.000152270903135417 0.0924043712970327 0.00966148754882001"
        rpy="0 0 0" />
      <mass
        value="0.417553118840387" />
      <inertia
        ixx="0.000778760838885271"
        ixy="-3.1319846533591E-05"
        ixz="9.73666822020879E-06"
        iyy="0.00074740822193102"
        iyz="0.000238313418273415"
        izz="0.00134923661677296" />
    </inertial>
    <visual>
      <origin
        xyz="0 0 0"
        rpy="0 0 0" />
      <geometry>
        <mesh
          filename="package://scorpio_arm_description_v3/meshes/link3.STL" />
      </geometry>
      <material
        name="">
        <color
          rgba="0.792156862745098 0.819607843137255 0.933333333333333 1" />
      </material>
    </visual>
    <collision>
      <origin
        xyz="0 0 0"
        rpy="0 0 0" />
      <geometry>
        <mesh
          filename="package://scorpio_arm_description_v3/meshes/link3.STL" />
      </geometry>
    </collision>
  </link>
  <joint
    name="joint3"
    type="revolute">
    <origin
      xyz="0 0.425000094137017 0.0409999999973247"
      rpy="0 0 0" />
    <parent
      link="link2" />
    <child
      link="link3" />
    <axis
      xyz="0 0 -1" />
  </joint>
  <link
    name="link4">
    <inertial>
      <origin
        xyz="-0.000109431918942657 0.077158563508547 0.125643446015501"
        rpy="0 0 0" />
      <mass
        value="0.389829536577821" />
      <inertia
        ixx="0.000675923696287507"
        ixy="1.42692185757278E-05"
        ixz="1.80236338044173E-05"
        iyy="0.000935956861167346"
        iyz="-0.000316733780223225"
        izz="0.000711962809217492" />
    </inertial>
    <visual>
      <origin
        xyz="0 0 0"
        rpy="0 0 0" />
      <geometry>
        <mesh
          filename="package://scorpio_arm_description_v3/meshes/link4.STL" />
      </geometry>
      <material
        name="">
        <color
          rgba="0.745098039215686 0.745098039215686 0.745098039215686 1" />
      </material>
    </visual>
    <collision>
      <origin
        xyz="0 0 0"
        rpy="0 0 0" />
      <geometry>
        <mesh
          filename="package://scorpio_arm_description_v3/meshes/link4.STL" />
      </geometry>
    </collision>
  </link>
  <joint
    name="jointt4"
    type="revolute">
    <origin
      xyz="-1.49404937263287E-05 0.227498306290618 -0.0332478801440056"
      rpy="1.5707963267949 0 3.14159265358979" />
    <parent
      link="link3" />
    <child
      link="link4" />
    <axis
      xyz="0 0 1" />
  </joint>
  <link
    name="link5">
    <inertial>
      <origin
        xyz="-0.0164538792900365 -0.0131997782617819 0.0535428562871828"
        rpy="0 0 0" />
      <mass
        value="0.0811646525056535" />
      <inertia
        ixx="3.82416724069144E-05"
        ixy="-3.5180959108023E-05"
        ixz="2.21993678801651E-07"
        iyy="7.49045940980443E-05"
        iyz="3.14976478834891E-06"
        izz="9.12568490681769E-05" />
    </inertial>
    <visual>
      <origin
        xyz="0 0 0"
        rpy="0 0 0" />
      <geometry>
        <mesh
          filename="package://scorpio_arm_description_v3/meshes/link5.STL" />
      </geometry>
      <material
        name="">
        <color
          rgba="0.752941176470588 0.752941176470588 0.752941176470588 1" />
      </material>
    </visual>
    <collision>
      <origin
        xyz="0 0 0"
        rpy="0 0 0" />
      <geometry>
        <mesh
          filename="package://scorpio_arm_description_v3/meshes/link5.STL" />
      </geometry>
    </collision>
  </link>
  <joint
    name="joint5"
    type="revolute">
    <origin
      xyz="1.61883599970582E-05 0.0570007543469901 0.197500000000056"
      rpy="1.5707963267949 0 0" />
    <parent
      link="link4" />
    <child
      link="link5" />
    <axis
      xyz="0 0 1" />
  </joint>
  <link
    name="link6">
    <inertial>
      <origin
        xyz="0.0140802343930933 0.00071520282148415 -0.02424013994588"
        rpy="0 0 0" />
      <mass
        value="0.27456433038843" />
      <inertia
        ixx="0.000570513704789326"
        ixy="3.53601263287756E-05"
        ixz="-0.0001835018536269"
        iyy="0.000602989236811894"
        iyz="0.000127335543333261"
        izz="0.000179445348610673" />
    </inertial>
    <visual>
      <origin
        xyz="0 0 0"
        rpy="0 0 0" />
      <geometry>
        <mesh
          filename="package://scorpio_arm_description_v3/meshes/link6.STL" />
      </geometry>
      <material
        name="">
        <color
          rgba="0.752941176470588 0.752941176470588 0.752941176470588 1" />
      </material>
    </visual>
    <collision>
      <origin
        xyz="0 0 0"
        rpy="0 0 0" />
      <geometry>
        <mesh
          filename="package://scorpio_arm_description_v3/meshes/link6.STL" />
      </geometry>
    </collision>
  </link>
  <joint
    name="joint6"
    type="revolute">
    <origin
      xyz="-3.11288537899817E-05 0.0754015995721986 0.0570028742029768"
      rpy="-1.5707963267949 -1.04851706378525E-28 -2.11069071793014E-14" />
    <parent
      link="link5" />
    <child
      link="link6" />
    <axis
      xyz="0 0 1" />
  </joint>
</robot>