<robot
  name="scorpio_arm_description">
  <link
    name="base_link">
    <inertial>
      <origin
        xyz="0.00232855897367896 -0.000897854801303336 0.0320057015237684"
        rpy="0 0 0" />
      <mass
        value="2.11601478181474" />
      <inertia
        ixx="0.00202332024755147"
        ixy="5.23890004677074E-05"
        ixz="-0.000130749232995404"
        iyy="0.00131340091136875"
        iyz="0.00018053940978266"
        izz="0.000782866759403263" />
    </inertial>
    <visual>
      <origin
        xyz="0 0 0"
        rpy="0 0 0" />
      <geometry>
        <mesh
          filename="package://scorpio_arm_description/meshes/base_link.STL" />
      </geometry>
      <material
        name="">
        <color
          rgba="0.752941176470588 0.752941176470588 0.752941176470588 1" />
      </material>
    </visual>
    <collision>
      <origin
        xyz="0 0 0"
        rpy="0 0 0" />
      <geometry>
        <mesh
          filename="package://scorpio_arm_description/meshes/base_link.STL" />
      </geometry>
    </collision>
  </link>
  <link
    name="link1">
    <inertial>
      <origin
        xyz="-0.00047721176303382 0.00737171227561761 0.069826295949556"
        rpy="0 0 0" />
      <mass
        value="0.462790481374201" />
      <inertia
        ixx="0.000939965910200968"
        ixy="1.64506977486972E-06"
        ixz="-2.63906539352615E-05"
        iyy="0.00212746857726695"
        iyz="-0.000232679816143081"
        izz="0.00200259662994072" />
    </inertial>
    <visual>
      <origin
        xyz="0 0 0"
        rpy="0 0 0" />
      <geometry>
        <mesh
          filename="package://scorpio_arm_description/meshes/link1.STL" />
      </geometry>
      <material
        name="">
        <color
          rgba="0.752941176470588 0.752941176470588 0.752941176470588 1" />
      </material>
    </visual>
    <collision>
      <origin
        xyz="0 0 0"
        rpy="0 0 0" />
      <geometry>
        <mesh
          filename="package://scorpio_arm_description/meshes/link1.STL" />
      </geometry>
    </collision>
  </link>
  <joint
    name="joint1"
    type="continuous">
    <origin
      xyz="0 0 0.109"
      rpy="0 -1.68946233269676E-34 2.86985925493723E-42" />
    <parent
      link="base_link" />
    <child
      link="link1" />
    <axis
      xyz="0 0 1" />
  </joint>
  <link
    name="link2">
    <inertial>
      <origin
        xyz="0.0356207658438776 0.0229148513796802 0.351921300641279"
        rpy="0 0 0" />
      <mass
        value="0.449209187922238" />
      <inertia
        ixx="0.00151413618405906"
        ixy="-1.70798752238207E-05"
        ixz="-0.000154451499942884"
        iyy="0.00223846678849402"
        iyz="-0.00025974327334332"
        izz="0.000822202626582776" />
    </inertial>
    <visual>
      <origin
        xyz="0 0 0"
        rpy="0 0 0" />
      <geometry>
        <mesh
          filename="package://scorpio_arm_description/meshes/link2.STL" />
      </geometry>
      <material
        name="">
        <color
          rgba="0.752941176470588 0.752941176470588 0.752941176470588 1" />
      </material>
    </visual>
    <collision>
      <origin
        xyz="0 0 0"
        rpy="0 0 0" />
      <geometry>
        <mesh
          filename="package://scorpio_arm_description/meshes/link2.STL" />
      </geometry>
    </collision>
  </link>
  <joint
    name="joint2"
    type="continuous">
    <origin
      xyz="0 0.00875000311574248 0.316999999914016"
      rpy="1.65436122510606E-24 -3.85185988877447E-34 -1.77925042286121E-10" />
    <parent
      link="link1" />
    <child
      link="link2" />
    <axis
      xyz="0 1 0" />
  </joint>
  <link
    name="link3">
    <inertial>
      <origin
        xyz="0.000152269114175846 -0.0106614865263226 0.0924043649935187"
        rpy="0 0 0" />
      <mass
        value="0.417553087871641" />
      <inertia
        ixx="0.000778760909534513"
        ixy="-9.73666840269503E-06"
        ixz="-3.13197319074789E-05"
        iyy="0.00134923667274817"
        iyz="-0.000238313439829515"
        izz="0.000747408217128288" />
    </inertial>
    <visual>
      <origin
        xyz="0 0 0"
        rpy="0 0 0" />
      <geometry>
        <mesh
          filename="package://scorpio_arm_description/meshes/link3.STL" />
      </geometry>
      <material
        name="">
        <color
          rgba="0.752941176470588 0.752941176470588 0.752941176470588 1" />
      </material>
    </visual>
    <collision>
      <origin
        xyz="0 0 0"
        rpy="0 0 0" />
      <geometry>
        <mesh
          filename="package://scorpio_arm_description/meshes/link3.STL" />
      </geometry>
    </collision>
  </link>
  <joint
    name="joint3"
    type="continuous">
    <origin
      xyz="0.0422907473805048 -0.0409999958029054 0.422890734166716"
      rpy="-1.65436122510606E-24 2.16239755607771E-34 1.77925042286121E-10" />
    <parent
      link="link2" />
    <child
      link="link3" />
    <axis
      xyz="0 1 0" />
  </joint>
  <link
    name="link4">
    <inertial>
      <origin
        xyz="0.000109432285690707 -0.0771585633041802 0.124643447255016"
        rpy="0 0 0" />
      <mass
        value="0.389829530881586" />
      <inertia
        ixx="0.000675923705557469"
        ixy="1.42692040003403E-05"
        ixz="-1.8023626728298E-05"
        iyy="0.000935956868372257"
        iyz="0.000316733783207625"
        izz="0.000711962805348924" />
    </inertial>
    <visual>
      <origin
        xyz="0 0 0"
        rpy="0 0 0" />
      <geometry>
        <mesh
          filename="package://scorpio_arm_description/meshes/link4.STL" />
      </geometry>
      <material
        name="">
        <color
          rgba="0.745098039215686 0.745098039215686 0.745098039215686 1" />
      </material>
    </visual>
    <collision>
      <origin
        xyz="0 0 0"
        rpy="0 0 0" />
      <geometry>
        <mesh
          filename="package://scorpio_arm_description/meshes/link4.STL" />
      </geometry>
    </collision>
  </link>
  <joint
    name="joint4"
    type="continuous">
    <origin
      xyz="-1.49404937540148E-05 0.0322478823721251 0.228498305973538"
      rpy="0 -1.68946233269676E-34 2.86985925493723E-42" />
    <parent
      link="link3" />
    <child
      link="link4" />
    <axis
      xyz="0 0 1" />
  </joint>
  <link
    name="link5">
    <inertial>
      <origin
        xyz="-0.0132001765719636 0.0540429524579847 -0.016454061247531"
        rpy="0 0 0" />
      <mass
        value="0.0811653306860956" />
      <inertia
        ixx="7.49049082009096E-05"
        ixy="3.14990479310913E-06"
        ixz="-3.51814648567066E-05"
        iyy="9.12577041844239E-05"
        iyz="2.2211571600285E-07"
        izz="3.82422818894536E-05" />
    </inertial>
    <visual>
      <origin
        xyz="0 0 0"
        rpy="0 0 0" />
      <geometry>
        <mesh
          filename="package://scorpio_arm_description/meshes/link5.STL" />
      </geometry>
      <material
        name="">
        <color
          rgba="0.752941176470588 0.752941176470588 0.752941176470588 1" />
      </material>
    </visual>
    <collision>
      <origin
        xyz="0 0 0"
        rpy="0 0 0" />
      <geometry>
        <mesh
          filename="package://scorpio_arm_description/meshes/link5.STL" />
      </geometry>
    </collision>
  </link>
  <joint
    name="joint5"
    type="continuous">
    <origin
      xyz="-1.61883600107299E-05 -0.0575007524250337 0.19650000056517"
      rpy="0 -1.68946233269676E-34 2.86985925493723E-42" />
    <parent
      link="link4" />
    <child
      link="link5" />
    <axis
      xyz="0 1 0" />
  </joint>
  <link
    name="link6">
    <inertial>
      <origin
        xyz="0.00134520090922445 0.00891683400651307 0.0202838597478301"
        rpy="0 0 0" />
      <mass
        value="0.186980321011871" />
      <inertia
        ixx="0.000107455605069503"
        ixy="1.96915014658434E-06"
        ixz="-9.01592677221931E-05"
        iyy="0.000196619540468262"
        iyz="-6.82364644197159E-06"
        izz="0.000137520250586052" />
    </inertial>
    <visual>
      <origin
        xyz="0 0 0"
        rpy="0 0 0" />
      <geometry>
        <mesh
          filename="package://scorpio_arm_description/meshes/link6.STL" />
      </geometry>
      <material
        name="">
        <color
          rgba="0.752941176470588 0.752941176470588 0.752941176470588 1" />
      </material>
    </visual>
    <collision>
      <origin
        xyz="0 0 0"
        rpy="0 0 0" />
      <geometry>
        <mesh
          filename="package://scorpio_arm_description/meshes/link6.STL" />
      </geometry>
    </collision>
  </link>
  <joint
    name="joint6"
    type="continuous">
    <origin
      xyz="0.0753999562300418 0.0575000019805965 0"
      rpy="0 -1.68946233269676E-34 2.86985925493723E-42" />
    <parent
      link="link5" />
    <child
      link="link6" />
    <axis
      xyz="-1 0 0" />
  </joint>
</robot>