<robot
  name="scorpio_arm_description">
  <link
    name="base_link">
    <inertial>
      <origin
        xyz="0.00231747398701783 -0.000926090336211632 0.0320057013975579"
        rpy="0 0 0" />
      <mass
        value="2.11601477785117" />
      <inertia
        ixx="0.00202448875114448"
        ixy="4.37456321748157E-05"
        ixz="-0.000128545243641073"
        iyy="0.00131223237033612"
        iyz="0.000182115234089426"
        izz="0.000782866740229641" />
    </inertial>
    <visual>
      <origin
        xyz="0 0 0"
        rpy="0 0 0" />
      <geometry>
        <mesh
          filename="package://scorpio_arm_description/meshes/base_link.STL" />
      </geometry>
      <material
        name="">
        <color
          rgba="0.792156862745098 0.819607843137255 0.933333333333333 1" />
      </material>
    </visual>
    <collision>
      <origin
        xyz="0 0 0"
        rpy="0 0 0" />
      <geometry>
        <mesh
          filename="package://scorpio_arm_description/meshes/base_link.STL" />
      </geometry>
    </collision>
  </link>
  <link
    name="link1">
    <inertial>
      <origin
        xyz="-0.00047721 0.0073717 0.067326"
        rpy="0 0 0" />
      <mass
        value="0.46279" />
      <inertia
        ixx="0.00093997"
        ixy="1.6451E-06"
        ixz="-2.6391E-05"
        iyy="0.0021275"
        iyz="-0.00023268"
        izz="0.0020026" />
    </inertial>
    <visual>
      <origin
        xyz="0 0 0"
        rpy="0 0 0" />
      <geometry>
        <mesh
          filename="package://scorpio_arm_description/meshes/link1.STL" />
      </geometry>
      <material
        name="">
        <color
          rgba="0.75294 0.75294 0.75294 1" />
      </material>
    </visual>
    <collision>
      <origin
        xyz="0 0 0"
        rpy="0 0 0" />
      <geometry>
        <mesh
          filename="package://scorpio_arm_description/meshes/link1.STL" />
      </geometry>
    </collision>
  </link>
  <joint
    name="joint1"
    type="continuous">
    <origin
      xyz="0 0 0.1115"
      rpy="0 -1.6895E-34 2.8699E-42" />
    <parent
      link="base_link" />
    <child
      link="link1" />
    <axis
      xyz="0 0 1" />
  </joint>
  <link
    name="link2">
    <inertial>
      <origin
        xyz="0.00042457 0.023915 0.35372"
        rpy="0 0 0" />
      <mass
        value="0.4492" />
      <inertia
        ixx="0.0015379"
        ixy="8.8533E-06"
        ixz="-8.2884E-05"
        iyy="0.0022385"
        iyz="-0.00026015"
        izz="0.00079847" />
    </inertial>
    <visual>
      <origin
        xyz="0 0 0"
        rpy="0 0 0" />
      <geometry>
        <mesh
          filename="package://scorpio_arm_description/meshes/link2.STL" />
      </geometry>
      <material
        name="">
        <color
          rgba="0.75294 0.75294 0.75294 1" />
      </material>
    </visual>
    <collision>
      <origin
        xyz="0 0 0"
        rpy="0 0 0" />
      <geometry>
        <mesh
          filename="package://scorpio_arm_description/meshes/link2.STL" />
      </geometry>
    </collision>
  </link>
  <joint
    name="joint2"
    type="continuous">
    <origin
      xyz="0 0.00775 0.3145"
      rpy="0 -1.6895E-34 2.8699E-42" />
    <parent
      link="link1" />
    <child
      link="link2" />
    <axis
      xyz="0 1 0" />
  </joint>
  <link
    name="link3">
    <inertial>
      <origin
        xyz="0.00015227 -0.0096615 0.092404"
        rpy="0 0 0" />
      <mass
        value="0.41755" />
      <inertia
        ixx="0.00077876"
        ixy="-9.7367E-06"
        ixz="-3.132E-05"
        iyy="0.0013492"
        iyz="-0.00023831"
        izz="0.00074741" />
    </inertial>
    <visual>
      <origin
        xyz="0 0 0"
        rpy="0 0 0" />
      <geometry>
        <mesh
          filename="package://scorpio_arm_description/meshes/link3.STL" />
      </geometry>
      <material
        name="">
        <color
          rgba="0.75294 0.75294 0.75294 1" />
      </material>
    </visual>
    <collision>
      <origin
        xyz="0 0 0"
        rpy="0 0 0" />
      <geometry>
        <mesh
          filename="package://scorpio_arm_description/meshes/link3.STL" />
      </geometry>
    </collision>
  </link>
  <joint
    name="joint3"
    type="continuous">
    <origin
      xyz="0 -0.041 0.425"
      rpy="0 -1.6895E-34 2.8699E-42" />
    <parent
      link="link2" />
    <child
      link="link3" />
    <axis
      xyz="0 1 0" />
  </joint>
  <link
    name="link4">
    <inertial>
      <origin
        xyz="-0.029263 -0.077159 0.12654"
        rpy="0 0 0" />
      <mass
        value="0.38983" />
      <inertia
        ixx="0.00067592"
        ixy="1.4269E-05"
        ixz="-1.8024E-05"
        iyy="0.00093596"
        iyz="0.00031673"
        izz="0.00071196" />
    </inertial>
    <visual>
      <origin
        xyz="0 0 0"
        rpy="0 0 0" />
      <geometry>
        <mesh
          filename="package://scorpio_arm_description/meshes/link4.STL" />
      </geometry>
      <material
        name="">
        <color
          rgba="0.7451 0.7451 0.7451 1" />
      </material>
    </visual>
    <collision>
      <origin
        xyz="0 0 0"
        rpy="0 0 0" />
      <geometry>
        <mesh
          filename="package://scorpio_arm_description/meshes/link4.STL" />
      </geometry>
    </collision>
  </link>
  <joint
    name="joint4"
    type="continuous">
    <origin
      xyz="0.029357 0.033248 0.2266"
      rpy="0 -1.6895E-34 2.8699E-42" />
    <parent
      link="link3" />
    <child
      link="link4" />
    <axis
      xyz="0 0 1" />
  </joint>
  <link
    name="link5">
    <inertial>
      <origin
        xyz="-0.067831 0.054043 -0.012932"
        rpy="0 0 0" />
      <mass
        value="0.081165" />
      <inertia
        ixx="7.4905E-05"
        ixy="3.1498E-06"
        ixz="-3.5181E-05"
        iyy="9.1257E-05"
        iyz="2.2199E-07"
        izz="3.8242E-05" />
    </inertial>
    <visual>
      <origin
        xyz="0 0 0"
        rpy="0 0 0" />
      <geometry>
        <mesh
          filename="package://scorpio_arm_description/meshes/link5.STL" />
      </geometry>
      <material
        name="">
        <color
          rgba="0.75294 0.75294 0.75294 1" />
      </material>
    </visual>
    <collision>
      <origin
        xyz="0 0 0"
        rpy="0 0 0" />
      <geometry>
        <mesh
          filename="package://scorpio_arm_description/meshes/link5.STL" />
      </geometry>
    </collision>
  </link>
  <joint
    name="joint5"
    type="continuous">
    <origin
      xyz="0.025243 -0.057501 0.19487"
      rpy="0 -1.6895E-34 2.8699E-42" />
    <parent
      link="link4" />
    <child
      link="link5" />
    <axis
      xyz="0 1 0" />
  </joint>
  <link
    name="link6">
    <inertial>
      <origin
        xyz="0.0013452 0.0089168 0.020284"
        rpy="0 0 0" />
      <mass
        value="0.18698" />
      <inertia
        ixx="0.00010746"
        ixy="1.9692E-06"
        ixz="-9.0159E-05"
        iyy="0.00019662"
        iyz="-6.8236E-06"
        izz="0.00013752" />
    </inertial>
    <visual>
      <origin
        xyz="0 0 0"
        rpy="0 0 0" />
      <geometry>
        <mesh
          filename="package://scorpio_arm_description/meshes/link6.STL" />
      </geometry>
      <material
        name="">
        <color
          rgba="0.75294 0.75294 0.75294 1" />
      </material>
    </visual>
    <collision>
      <origin
        xyz="0 0 0"
        rpy="0 0 0" />
      <geometry>
        <mesh
          filename="package://scorpio_arm_description/meshes/link6.STL" />
      </geometry>
    </collision>
  </link>
  <joint
    name="joint6"
    type="continuous">
    <origin
      xyz="0.020769 0.0575 0.0035219"
      rpy="0 -1.6895E-34 2.8699E-42" />
    <parent
      link="link5" />
    <child
      link="link6" />
    <axis
      xyz="-1 0 0" />
  </joint>
</robot>