<robot
  name="scorpio_arm_description">
  <link
    name="base_link">
    <inertial>
      <origin
        xyz="0.00231747398701783 -0.000926090336211632 0.0320057013975578"
        rpy="0 0 0" />
      <mass
        value="2.11601477785117" />
      <inertia
        ixx="0.00202448875114448"
        ixy="4.37456321748157E-05"
        ixz="-0.000128545243641073"
        iyy="0.00131223237033612"
        iyz="0.000182115234089426"
        izz="0.000782866740229642" />
    </inertial>
    <visual>
      <origin
        xyz="0 0 0"
        rpy="0 0 0" />
      <geometry>
        <mesh
          filename="package://scorpio_arm_description/meshes/base_link.STL" />
      </geometry>
      <material
        name="">
        <color
          rgba="0.792156862745098 0.819607843137255 0.933333333333333 1" />
      </material>
    </visual>
    <collision>
      <origin
        xyz="0 0 0"
        rpy="0 0 0" />
      <geometry>
        <mesh
          filename="package://scorpio_arm_description/meshes/base_link.STL" />
      </geometry>
    </collision>
  </link>
  <link
    name="link1">
    <inertial>
      <origin
        xyz="-0.000477211763040624 0.00737171225105655 0.0673262959495374"
        rpy="0 0 0" />
      <mass
        value="0.462790481374203" />
      <inertia
        ixx="0.000939965910200995"
        ixy="1.64506977488465E-06"
        ixz="-2.63906539352485E-05"
        iyy="0.00212746857726697"
        iyz="-0.000232679816143088"
        izz="0.00200259662994076" />
    </inertial>
    <visual>
      <origin
        xyz="0 0 0"
        rpy="0 0 0" />
      <geometry>
        <mesh
          filename="package://scorpio_arm_description/meshes/link1.STL" />
      </geometry>
      <material
        name="">
        <color
          rgba="0.752941176470588 0.752941176470588 0.752941176470588 1" />
      </material>
    </visual>
    <collision>
      <origin
        xyz="0 0 0"
        rpy="0 0 0" />
      <geometry>
        <mesh
          filename="package://scorpio_arm_description/meshes/link1.STL" />
      </geometry>
    </collision>
  </link>
  <joint
    name="joint1"
    type="continuous">
    <origin
      xyz="0 0 0.1115"
      rpy="0 -1.68946233269676E-34 2.86985925493723E-42" />
    <parent
      link="base_link" />
    <child
      link="link1" />
    <axis
      xyz="0 0 1" />
  </joint>
  <link
    name="link2">
    <inertial>
      <origin
        xyz="0.000424568456047723 0.0239145519245712 0.353718613303074"
        rpy="0 0 0" />
      <mass
        value="0.449203640099039" />
      <inertia
        ixx="0.00153786121682174"
        ixy="8.85331100200266E-06"
        ixz="-8.28836535512739E-05"
        iyy="0.00223846447461806"
        iyz="-0.000260149197807529"
        izz="0.000798472797086813" />
    </inertial>
    <visual>
      <origin
        xyz="0 0 0"
        rpy="0 0 0" />
      <geometry>
        <mesh
          filename="package://scorpio_arm_description/meshes/link2.STL" />
      </geometry>
      <material
        name="">
        <color
          rgba="0.752941176470588 0.752941176470588 0.752941176470588 1" />
      </material>
    </visual>
    <collision>
      <origin
        xyz="0 0 0"
        rpy="0 0 0" />
      <geometry>
        <mesh
          filename="package://scorpio_arm_description/meshes/link2.STL" />
      </geometry>
    </collision>
  </link>
  <joint
    name="joint2"
    type="continuous">
    <origin
      xyz="0 0.00775000309120119 0.314499999923826"
      rpy="0 -1.68946233269676E-34 2.86985925493723E-42" />
    <parent
      link="link1" />
    <child
      link="link2" />
    <axis
      xyz="0 1 0" />
  </joint>
  <link
    name="link3">
    <inertial>
      <origin
        xyz="0.000152269107736667 -0.00966148651756621 0.0924043649918139"
        rpy="0 0 0" />
      <mass
        value="0.417553087898504" />
      <inertia
        ixx="0.000778760909408358"
        ixy="-9.73666839171344E-06"
        ixz="-3.13197319968024E-05"
        iyy="0.0013492366724475"
        iyz="-0.000238313439761673"
        izz="0.000747408216873425" />
    </inertial>
    <visual>
      <origin
        xyz="0 0 0"
        rpy="0 0 0" />
      <geometry>
        <mesh
          filename="package://scorpio_arm_description/meshes/link3.STL" />
      </geometry>
      <material
        name="">
        <color
          rgba="0.752941176470588 0.752941176470588 0.752941176470588 1" />
      </material>
    </visual>
    <collision>
      <origin
        xyz="0 0 0"
        rpy="0 0 0" />
      <geometry>
        <mesh
          filename="package://scorpio_arm_description/meshes/link3.STL" />
      </geometry>
    </collision>
  </link>
  <joint
    name="joint3"
    type="continuous">
    <origin
      xyz="0 -0.0409999957917564 0.425000094540175"
      rpy="0 -1.68946233269676E-34 2.86985925493723E-42" />
    <parent
      link="link2" />
    <child
      link="link3" />
    <axis
      xyz="0 1 0" />
  </joint>
  <link
    name="link4">
    <inertial>
      <origin
        xyz="-0.0292627499425984 -0.0771585631646571 0.126537188719397"
        rpy="0 0 0" />
      <mass
        value="0.389829532509614" />
      <inertia
        ixx="0.000675923697644024"
        ixy="1.42692007374336E-05"
        ixz="-1.80236102430747E-05"
        iyy="0.000935956860043861"
        iyz="0.00031673377995729"
        izz="0.000711962802670113" />
    </inertial>
    <visual>
      <origin
        xyz="0 0 0"
        rpy="0 0 0" />
      <geometry>
        <mesh
          filename="package://scorpio_arm_description/meshes/link4.STL" />
      </geometry>
      <material
        name="">
        <color
          rgba="0.745098039215686 0.745098039215686 0.745098039215686 1" />
      </material>
    </visual>
    <collision>
      <origin
        xyz="0 0 0"
        rpy="0 0 0" />
      <geometry>
        <mesh
          filename="package://scorpio_arm_description/meshes/link4.STL" />
      </geometry>
    </collision>
  </link>
  <joint
    name="joint4"
    type="continuous">
    <origin
      xyz="0.0293572423190065 0.0332478823524079 0.226604563890855"
      rpy="0 -1.68946233269676E-34 2.86985925493723E-42" />
    <parent
      link="link3" />
    <child
      link="link4" />
    <axis
      xyz="0 0 1" />
  </joint>
  <link
    name="link5">
    <inertial>
      <origin
        xyz="-0.0678313661060441 0.0540429524925939 -0.0129322011465105"
        rpy="0 0 0" />
      <mass
        value="0.0811653306860973" />
      <inertia
        ixx="7.49049082009068E-05"
        ixy="3.14990479310849E-06"
        ixz="-3.51814648567066E-05"
        iyy="9.12577041844226E-05"
        iyz="2.22115716001488E-07"
        izz="3.82422818894546E-05" />
    </inertial>
    <visual>
      <origin
        xyz="0 0 0"
        rpy="0 0 0" />
      <geometry>
        <mesh
          filename="package://scorpio_arm_description/meshes/link5.STL" />
      </geometry>
      <material
        name="">
        <color
          rgba="0.752941176470588 0.752941176470588 0.752941176470588 1" />
      </material>
    </visual>
    <collision>
      <origin
        xyz="0 0 0"
        rpy="0 0 0" />
      <geometry>
        <mesh
          filename="package://scorpio_arm_description/meshes/link5.STL" />
      </geometry>
    </collision>
  </link>
  <joint
    name="joint5"
    type="continuous">
    <origin
      xyz="0.0252428183612949 -0.0575007524410362 0.194871882536996"
      rpy="0 -1.68946233269676E-34 2.86985925493723E-42" />
    <parent
      link="link4" />
    <child
      link="link5" />
    <axis
      xyz="0 1 0" />
  </joint>
  <link
    name="link6">
    <inertial>
      <origin
        xyz="0.00134519983318483 0.00891683487478738 0.0202838590640517"
        rpy="0 0 0" />
      <mass
        value="0.186980317490548" />
      <inertia
        ixx="0.000107455596105274"
        ixy="1.96914206983284E-06"
        ixz="-9.01592606687711E-05"
        iyy="0.000196619525212781"
        iyz="-6.82365205218553E-06"
        izz="0.000137520235590888" />
    </inertial>
    <visual>
      <origin
        xyz="0 0 0"
        rpy="0 0 0" />
      <geometry>
        <mesh
          filename="package://scorpio_arm_description/meshes/link6.STL" />
      </geometry>
      <material
        name="">
        <color
          rgba="0.752941176470588 0.752941176470588 0.752941176470588 1" />
      </material>
    </visual>
    <collision>
      <origin
        xyz="0 0 0"
        rpy="0 0 0" />
      <geometry>
        <mesh
          filename="package://scorpio_arm_description/meshes/link6.STL" />
      </geometry>
    </collision>
  </link>
  <joint
    name="joint6"
    type="continuous">
    <origin
      xyz="0.020768766695969 0.0575000020152065 0.00352185941324046"
      rpy="0 -1.68946233269676E-34 2.86985925493723E-42" />
    <parent
      link="link5" />
    <child
      link="link6" />
    <axis
      xyz="-1 0 0" />
  </joint>
</robot>