<robot
  name="scorpio_arm_description">
  <link
    name="base_link">
    <inertial>
      <origin
        xyz="0.00241298294936865 -0.00092695723398336 0.0319855882409883"
        rpy="0 0 0" />
      <mass
        value="2.11403658212985" />
      <inertia
        ixx="0.00202357226169826"
        ixy="4.35584720220044E-05"
        ixz="-0.000132889206048489"
        iyy="0.00129068990477557"
        iyz="0.000182154653449064"
        izz="0.000762237374925334" />
    </inertial>
    <visual>
      <origin
        xyz="0 0 0"
        rpy="0 0 0" />
      <geometry>
        <mesh
          filename="package://scorpio_arm_description/meshes/base_link.STL" />
      </geometry>
      <material
        name="">
        <color
          rgba="0.792156862745098 0.819607843137255 0.933333333333333 1" />
      </material>
    </visual>
    <collision>
      <origin
        xyz="0 0 0"
        rpy="0 0 0" />
      <geometry>
        <mesh
          filename="package://scorpio_arm_description/meshes/base_link.STL" />
      </geometry>
    </collision>
  </link>
  <link
    name="axis1_link">
    <inertial>
      <origin
        xyz="-0.00052805130129154 -0.00236324420197201 0.0636362765269718"
        rpy="0 0 0" />
      <mass
        value="0.417651221574078" />
      <inertia
        ixx="0.000370096751509036"
        ixy="3.76685673992046E-06"
        ixz="-2.50358388373324E-05"
        iyy="0.00191657720999125"
        iyz="2.53499116616611E-05"
        izz="0.00154997503669375" />
    </inertial>
    <visual>
      <origin
        xyz="0 0 0"
        rpy="0 0 0" />
      <geometry>
        <mesh
          filename="package://scorpio_arm_description/meshes/axis1_link.STL" />
      </geometry>
      <material
        name="">
        <color
          rgba="0.792156862745098 0.819607843137255 0.933333333333333 1" />
      </material>
    </visual>
    <collision>
      <origin
        xyz="0 0 0"
        rpy="0 0 0" />
      <geometry>
        <mesh
          filename="package://scorpio_arm_description/meshes/axis1_link.STL" />
      </geometry>
    </collision>
  </link>
  <joint
    name="joint1"
    type="revolute">
    <origin
      xyz="0 0 0.109"
      rpy="0 0 0" />
    <parent
      link="base_link" />
    <child
      link="axis1_link" />
    <axis
      xyz="0 0 1" />
  </joint>
  <link
    name="axis2_link">
    <inertial>
      <origin
        xyz="0.000391322250571292 0.0259973254802041 0.364443673798772"
        rpy="0 0 0" />
      <mass
        value="0.408183489607471" />
      <inertia
        ixx="0.00091365837595308"
        ixy="8.55669406678968E-06"
        ixz="-8.45827149151966E-05"
        iyy="0.00162175045550475"
        iyz="-0.000158468982052778"
        izz="0.000767106762734368" />
    </inertial>
    <visual>
      <origin
        xyz="0 0 0"
        rpy="0 0 0" />
      <geometry>
        <mesh
          filename="package://scorpio_arm_description/meshes/axis2_link.STL" />
      </geometry>
      <material
        name="">
        <color
          rgba="0.792156862745098 0.819607843137255 0.933333333333333 1" />
      </material>
    </visual>
    <collision>
      <origin
        xyz="0 0 0"
        rpy="0 0 0" />
      <geometry>
        <mesh
          filename="package://scorpio_arm_description/meshes/axis2_link.STL" />
      </geometry>
    </collision>
  </link>
  <joint
    name="joint2"
    type="revolute">
    <origin
      xyz="0 0.00775000000340304 0.317000000000005"
      rpy="0 0 0" />
    <parent
      link="axis1_link" />
    <child
      link="axis2_link" />
    <axis
      xyz="0 1 0" />
  </joint>
  <link
    name="axis3_link">
    <inertial>
      <origin
        xyz="-0.000791230526605243 -0.0123901753946604 0.0897049662007631"
        rpy="0 0 0" />
      <mass
        value="0.396254971401712" />
      <inertia
        ixx="0.000533747072361712"
        ixy="6.43972921623871E-06"
        ixz="2.06940349981403E-06"
        iyy="0.00112961518158255"
        iyz="-0.000162143013025069"
        izz="0.000705795430840765" />
    </inertial>
    <visual>
      <origin
        xyz="0 0 0"
        rpy="0 0 0" />
      <geometry>
        <mesh
          filename="package://scorpio_arm_description/meshes/axis3_link.STL" />
      </geometry>
      <material
        name="">
        <color
          rgba="0.792156862745098 0.819607843137255 0.933333333333333 1" />
      </material>
    </visual>
    <collision>
      <origin
        xyz="0 0 0"
        rpy="0 0 0" />
      <geometry>
        <mesh
          filename="package://scorpio_arm_description/meshes/axis3_link.STL" />
      </geometry>
    </collision>
  </link>
  <joint
    name="joint3"
    type="revolute">
    <origin
      xyz="0 -0.0400000000007079 0.424999999999929"
      rpy="0 0 0" />
    <parent
      link="axis2_link" />
    <child
      link="axis3_link" />
    <axis
      xyz="0 1 0" />
  </joint>
  <link
    name="axis4_link">
    <inertial>
      <origin
        xyz="-0.0314569234909521 -0.0744346535829572 0.100850474163568"
        rpy="0 0 0" />
      <mass
        value="0.201499067547436" />
      <inertia
        ixx="0.00045540791713047"
        ixy="-5.93341442090208E-05"
        ixz="9.01387774684072E-05"
        iyy="0.000371147078558663"
        iyz="0.000208806549007292"
        izz="0.000190286125303257" />
    </inertial>
    <visual>
      <origin
        xyz="0 0 0"
        rpy="0 0 0" />
      <geometry>
        <mesh
          filename="package://scorpio_arm_description/meshes/axis4_link.STL" />
      </geometry>
      <material
        name="">
        <color
          rgba="0.792156862745098 0.819607843137255 0.933333333333333 1" />
      </material>
    </visual>
    <collision>
      <origin
        xyz="0 0 0"
        rpy="0 0 0" />
      <geometry>
        <mesh
          filename="package://scorpio_arm_description/meshes/axis4_link.STL" />
      </geometry>
    </collision>
  </link>
  <joint
    name="joint4"
    type="revolute">
    <origin
      xyz="1.61883598461393E-05 0.0322507543563791 0.247499999999955"
      rpy="0 -1.224606E-16 0" />
    <parent
      link="axis3_link" />
    <child
      link="axis4_link" />
    <axis
      xyz="0 0 1" />
  </joint>
  <link
    name="axis5_link">
    <inertial>
      <origin
        xyz="0.0304993807697848 0.0564926297482536 -0.0231310317734645"
        rpy="0 0 0" />
      <mass
        value="0.0552722309654787" />
      <inertia
        ixx="0"
        ixy="0"
        ixz="0"
        iyy="0"
        iyz="0"
        izz="0" />
    </inertial>
    <visual>
      <origin
        xyz="0 0 0"
        rpy="0 0 0" />
      <geometry>
        <mesh
          filename="package://scorpio_arm_description/meshes/axis5_link.STL" />
      </geometry>
      <material
        name="">
        <color
          rgba="0.792156862745098 0.819607843137255 0.933333333333333 1" />
      </material>
    </visual>
    <collision>
      <origin
        xyz="0 0 0"
        rpy="0 0 0" />
      <geometry>
        <mesh
          filename="package://scorpio_arm_description/meshes/axis5_link.STL" />
      </geometry>
    </collision>
  </link>
  <joint
    name="joint5"
    type="revolute">
    <origin
      xyz="-1.61883600108781E-05 -0.0575007543599423 0.177499999999999"
      rpy="0 1.224606E-16 0" />
    <parent
      link="axis4_link" />
    <child
      link="axis5_link" />
    <axis
      xyz="0 1 0" />
  </joint>
  <link
    name="axis6_link">
    <inertial>
      <origin
        xyz="-0.0144665238693092 0.013025992366918 0.0710357803609774"
        rpy="0 0 0" />
      <mass
        value="0.112666642170327" />
      <inertia
        ixx="1.51083880207538E-05"
        ixy="1.5527602157708E-05"
        ixz="6.17469847458303E-06"
        iyy="2.05449267814695E-05"
        iyz="-5.18765426474927E-06"
        izz="3.15274748238579E-05" />
    </inertial>
    <visual>
      <origin
        xyz="0 0 0"
        rpy="0 0 0" />
      <geometry>
        <mesh
          filename="package://scorpio_arm_description/meshes/axis6_link.STL" />
      </geometry>
      <material
        name="">
        <color
          rgba="0.792156862745098 0.819607843137255 0.933333333333333 1" />
      </material>
    </visual>
    <collision>
      <origin
        xyz="0 0 0"
        rpy="0 0 0" />
      <geometry>
        <mesh
          filename="package://scorpio_arm_description/meshes/axis6_link.STL" />
      </geometry>
    </collision>
  </link>
  <joint
    name="jiont6"
    type="revolute">
    <origin
      xyz="0 0.0574999980191652 0"
      rpy="4.96764900171393E-15 -2.11069071793014E-14 -1.04851706378525E-28" />
    <parent
      link="axis5_link" />
    <child
      link="axis6_link" />
    <axis
      xyz="0 0 1" />
  </joint>
</robot>