<robot
  name="scorpio_arm_description">
  <link
    name="base_link">
    <inertial>
      <origin
        xyz="0.0019716460984453 -0.012785762257813 0.214352740235452"
        rpy="0 0 0" />
      <mass
        value="2.50584431442898" />
      <inertia
        ixx="0.456881131210235"
        ixy="2.22814339134445E-06"
        ixz="0.000711173304633452"
        iyy="0.454517409549147"
        iyz="0.0299138881314551"
        izz="0.00340958147405569" />
    </inertial>
    <visual>
      <origin
        xyz="0 0 0"
        rpy="0 0 0" />
      <geometry>
        <mesh
          filename="package://scorpio_arm_description/meshes/base_link.STL" />
      </geometry>
      <material
        name="">
        <color
          rgba="0.792156862745098 0.819607843137255 0.933333333333333 1" />
      </material>
    </visual>
    <collision>
      <origin
        xyz="0 0 0"
        rpy="0 0 0" />
      <geometry>
        <mesh
          filename="package://scorpio_arm_description/meshes/base_link.STL" />
      </geometry>
    </collision>
  </link>
  <link
    name="link1">
    <inertial>
      <origin
        xyz="-0.000477211763040641 0.00737171225105654 0.0673262959495374"
        rpy="0 0 0" />
      <mass
        value="0.462790481374203" />
      <inertia
        ixx="0.000939965910200995"
        ixy="1.64506977488471E-06"
        ixz="-2.63906539352484E-05"
        iyy="0.00212746857726697"
        iyz="-0.000232679816143088"
        izz="0.00200259662994076" />
    </inertial>
    <visual>
      <origin
        xyz="0 0 0"
        rpy="0 0 0" />
      <geometry>
        <mesh
          filename="package://scorpio_arm_description/meshes/link1.STL" />
      </geometry>
      <material
        name="">
        <color
          rgba="0.752941176470588 0.752941176470588 0.752941176470588 1" />
      </material>
    </visual>
    <collision>
      <origin
        xyz="0 0 0"
        rpy="0 0 0" />
      <geometry>
        <mesh
          filename="package://scorpio_arm_description/meshes/link1.STL" />
      </geometry>
    </collision>
  </link>
  <joint
    name="joint1"
    type="continuous">
    <origin
      xyz="0 0 0.1115"
      rpy="-1.65436122510606E-24 2.16239755607771E-34 1.77925042286121E-10" />
    <parent
      link="base_link" />
    <child
      link="link1" />
    <axis
      xyz="0 0 1" />
  </joint>
  <link
    name="link2">
    <inertial>
      <origin
        xyz="0.000424568456060143 0.353718613538131 -0.0239145484479154"
        rpy="0 0 0" />
      <mass
        value="0.449203640099022" />
      <inertia
        ixx="0.0015378612168218"
        ixy="-8.28836534643512E-05"
        ixz="-8.85331181664519E-06"
        iyy="0.00079847279197285"
        iyz="0.000260149183654036"
        izz="0.00223846447973205" />
    </inertial>
    <visual>
      <origin
        xyz="0 0 0"
        rpy="0 0 0" />
      <geometry>
        <mesh
          filename="package://scorpio_arm_description/meshes/link2.STL" />
      </geometry>
      <material
        name="">
        <color
          rgba="0.752941176470588 0.752941176470588 0.752941176470588 1" />
      </material>
    </visual>
    <collision>
      <origin
        xyz="0 0 0"
        rpy="0 0 0" />
      <geometry>
        <mesh
          filename="package://scorpio_arm_description/meshes/link2.STL" />
      </geometry>
    </collision>
  </link>
  <joint
    name="joint2"
    type="revolute">
    <origin
      xyz="0 0.00775000309120119 0.314499999923826"
      rpy="1.57079631696602 1.748803E-18 0" />
    <parent
      link="link1" />
    <child
      link="link2" />
    <axis
      xyz="0 0 -1" />
  </joint>
  <link
    name="link3">
    <inertial>
      <origin
        xyz="0.000152270903093772 0.0924043712968591 0.00966148757711546"
        rpy="0 0 0" />
      <mass
        value="0.417553118840387" />
      <inertia
        ixx="0.000778760838885269"
        ixy="-3.1319846533593E-05"
        ixz="9.73666822020838E-06"
        iyy="0.00074740822193102"
        iyz="0.000238313418273415"
        izz="0.00134923661677296" />
    </inertial>
    <visual>
      <origin
        xyz="0 0 0"
        rpy="0 0 0" />
      <geometry>
        <mesh
          filename="package://scorpio_arm_description/meshes/link3.STL" />
      </geometry>
      <material
        name="">
        <color
          rgba="0.752941176470588 0.752941176470588 0.752941176470588 1" />
      </material>
    </visual>
    <collision>
      <origin
        xyz="0 0 0"
        rpy="0 0 0" />
      <geometry>
        <mesh
          filename="package://scorpio_arm_description/meshes/link3.STL" />
      </geometry>
    </collision>
  </link>
  <joint
    name="joint3"
    type="revolute">
    <origin
      xyz="0 0.425000094137191 0.0409999999690292"
      rpy="0 0 0" />
    <parent
      link="link2" />
    <child
      link="link3" />
    <axis
      xyz="0 0 -1" />
  </joint>
  <link
    name="link4">
    <inertial>
      <origin
        xyz="0.000109431918928782 -0.0771585635179768 0.124643446015446"
        rpy="0 0 0" />
      <mass
        value="0.389829536577821" />
      <inertia
        ixx="0.000675923696287507"
        ixy="1.42692185757275E-05"
        ixz="-1.80236338044172E-05"
        iyy="0.000935956861167347"
        iyz="0.000316733780223225"
        izz="0.000711962809217492" />
    </inertial>
    <visual>
      <origin
        xyz="0 0 0"
        rpy="0 0 0" />
      <geometry>
        <mesh
          filename="package://scorpio_arm_description/meshes/link4.STL" />
      </geometry>
      <material
        name="">
        <color
          rgba="0.745098039215686 0.745098039215686 0.745098039215686 1" />
      </material>
    </visual>
    <collision>
      <origin
        xyz="0 0 0"
        rpy="0 0 0" />
      <geometry>
        <mesh
          filename="package://scorpio_arm_description/meshes/link4.STL" />
      </geometry>
    </collision>
  </link>
  <joint
    name="joint4"
    type="revolute">
    <origin
      xyz="-1.49404937541016E-05 0.228498306290499 -0.03324788012514"
      rpy="-1.5707963267949 0 0" />
    <parent
      link="link3" />
    <child
      link="link4" />
    <axis
      xyz="0 0 1" />
  </joint>
  <link
    name="link5">
    <inertial>
      <origin
        xyz="0.0132001765719637 -0.0164540607163493 0.0540429526197033"
        rpy="0 0 0" />
      <mass
        value="0.0811653306860956" />
      <inertia
        ixx="7.49049082009069E-05"
        ixy="3.51814648257455E-05"
        ixz="-3.14990513890253E-06"
        iyy="3.82422818938195E-05"
        iyz="2.22116237083292E-07"
        izz="9.12577041800548E-05" />
    </inertial>
    <visual>
      <origin
        xyz="0 0 0"
        rpy="0 0 0" />
      <geometry>
        <mesh
          filename="package://scorpio_arm_description/meshes/link5.STL" />
      </geometry>
      <material
        name="">
        <color
          rgba="0.752941176470588 0.752941176470588 0.752941176470588 1" />
      </material>
    </visual>
    <collision>
      <origin
        xyz="0 0 0"
        rpy="0 0 0" />
      <geometry>
        <mesh
          filename="package://scorpio_arm_description/meshes/link5.STL" />
      </geometry>
    </collision>
  </link>
  <joint
    name="joint5"
    type="revolute">
    <origin
      xyz="-1.61883600108297E-05 -0.0575007543564076 0.196500000000001"
      rpy="1.5707963267949 0 3.14159265358979" />
    <parent
      link="link4" />
    <child
      link="link5" />
    <axis
      xyz="0 0 1" />
  </joint>
  <link
    name="link6">
    <inertial>
      <origin
        xyz="0.00891683355181057 0.0202838591937038 0.0013451998345921"
        rpy="0 0 0" />
      <mass
        value="0.186980317446745" />
      <inertia
        ixx="0.000196619525906284"
        ixy="-6.8236441896507E-06"
        ixz="1.96915299826278E-06"
        iyy="0.000137520242557688"
        iyz="-9.01592610411392E-05"
        izz="0.000107455603746989" />
    </inertial>
    <visual>
      <origin
        xyz="0 0 0"
        rpy="0 0 0" />
      <geometry>
        <mesh
          filename="package://scorpio_arm_description/meshes/link6.STL" />
      </geometry>
      <material
        name="">
        <color
          rgba="0.752941176470588 0.752941176470588 0.752941176470588 1" />
      </material>
    </visual>
    <collision>
      <origin
        xyz="0 0 0"
        rpy="0 0 0" />
      <geometry>
        <mesh
          filename="package://scorpio_arm_description/meshes/link6.STL" />
      </geometry>
    </collision>
  </link>
  <joint
    name="joint6"
    type="revolute">
    <origin
      xyz="-0.0753999562300418 0 0.0575000019805907"
      rpy="3.14159265358979 -1.5707963267949 0" />
    <parent
      link="link5" />
    <child
      link="link6" />
    <axis
      xyz="0 0 -1" />
  </joint>
</robot>